Traceback (most recent call last):
  File "/usr/share/miniconda/envs/microdf/lib/python3.9/site-packages/jupyter_cache/executors/utils.py", line 51, in single_nb_execution
    executenb(
  File "/usr/share/miniconda/envs/microdf/lib/python3.9/site-packages/nbclient/client.py", line 1112, in execute
    return NotebookClient(nb=nb, resources=resources, km=km, **kwargs).execute()
  File "/usr/share/miniconda/envs/microdf/lib/python3.9/site-packages/nbclient/util.py", line 74, in wrapped
    return just_run(coro(*args, **kwargs))
  File "/usr/share/miniconda/envs/microdf/lib/python3.9/site-packages/nbclient/util.py", line 53, in just_run
    return loop.run_until_complete(coro)
  File "/usr/share/miniconda/envs/microdf/lib/python3.9/asyncio/base_events.py", line 642, in run_until_complete
    return future.result()
  File "/usr/share/miniconda/envs/microdf/lib/python3.9/site-packages/nbclient/client.py", line 553, in async_execute
    await self.async_execute_cell(
  File "/usr/share/miniconda/envs/microdf/lib/python3.9/site-packages/nbclient/client.py", line 857, in async_execute_cell
    self._check_raise_for_error(cell, exec_reply)
  File "/usr/share/miniconda/envs/microdf/lib/python3.9/site-packages/nbclient/client.py", line 760, in _check_raise_for_error
    raise CellExecutionError.from_cell_and_msg(cell, exec_reply_content)
nbclient.exceptions.CellExecutionError: An error occurred while executing the following cell:
------------------
mdf.set_plot_style()
------------------

[0;31m---------------------------------------------------------------------------[0m
[0;31mAttributeError[0m                            Traceback (most recent call last)
[0;32m<ipython-input-2-0a2924149170>[0m in [0;36m<module>[0;34m[0m
[0;32m----> 1[0;31m [0mmdf[0m[0;34m.[0m[0mset_plot_style[0m[0;34m([0m[0;34m)[0m[0;34m[0m[0;34m[0m[0m
[0m
[0;32m~/work/microdf/microdf/microdf/style.py[0m in [0;36mset_plot_style[0;34m(dpi)[0m
[1;32m     22[0m     [0;31m# Set up Roboto. Must be downloaded in the current directory.[0m[0;34m[0m[0;34m[0m[0;34m[0m[0m
[1;32m     23[0m     [0;31m# See https://stackoverflow.com/a/51844978/1840471.[0m[0;34m[0m[0;34m[0m[0;34m[0m[0m
[0;32m---> 24[0;31m     [0mfm[0m[0;34m.[0m[0mfontManager[0m[0;34m.[0m[0mttflist[0m [0;34m+=[0m [0mfm[0m[0;34m.[0m[0mcreateFontList[0m[0;34m([0m[0;34m[[0m[0;34m"Roboto-Regular.ttf"[0m[0;34m][0m[0;34m)[0m[0;34m[0m[0;34m[0m[0m
[0m[1;32m     25[0m [0;34m[0m[0m
[1;32m     26[0m     STYLE = {

[0;31mAttributeError[0m: module 'matplotlib.font_manager' has no attribute 'createFontList'
AttributeError: module 'matplotlib.font_manager' has no attribute 'createFontList'

